Workbook
Name AttackCoeff: 'BP Controls'!$B$6
Name AttackExp: 'BP Controls'!$B$7
Name DefCoeff: 'BP Controls'!$B$13
Name DefExp: 'BP Controls'!$B$14
Name DelayCoeff: 'BP Controls'!$B$15
Name DelayExp: 'BP Controls'!$B$16
Name ExpectedAttacks: 'BP Controls'!$B$28
Name HighCap: 'BP Controls'!$B$9
Name HighDecay: 'BP Controls'!$B$10
Name HighThreshold: 'BP Controls'!$B$8
Name MinRefundCap: 'BP Controls'!$B$23
Name MinRefundCoeff: 'BP Controls'!$B$22
Name NegDelayFloor: 'BP Controls'!$B$17
Name NegDelayRefund: 'BP Controls'!$B$18
Name OneHBP: 'BP Controls'!$B$5
Name PassiveBPTable: 'BP Controls'!$A$51:$C$78
Name PassiveNames: 'BP Controls'!$A$51:$A$67
Name PatternBPTable: 'BP Controls'!$A$44:$D$47
Name PatternCoeff: 'BP Controls'!$B$24
Name PatternExp: 'BP Controls'!$B$25
Name PatternNames: 'BP Controls'!$A$44:$A$47
Name RangeBase: 'BP Controls'!$B$19
Name RangeCoeff: 'BP Controls'!$B$20
Name RangeExp: 'BP Controls'!$B$21
Name RangeTable: 'BP Controls'!$A$33:$C$40
Name TargetBP: 'BP Controls'!$B$4
Name TempoCap: 'BP Controls'!$B$27
Name TempoFactor: 'BP Controls'!$B$26
Name WTCoeff: 'BP Controls'!$B$11
Name WTExp: 'BP Controls'!$B$12

Sheet Read Me
A1: CTRBLXAI Weapon BP Builder v3.1
A2: Build, audit, and stress-test approved or explicitly provisional base-weapon endpoints against the working ~1,000 BP model.
A4: Authority | B4: Newest approved decision > current Core Game Manual > current Architecture > this Builder > older files.
A5: Editing rule | B5: Only blue cells on Weapon Builder and Scenario are intended for normal editing. Gray cells are controls/reference; white cells calculate.
A6: Current timing | B6: Basic Attack RT = ROUND(Modified Base RT x 0.10) + Effective Weapon WT.
A7: Complete-cycle rule | B7: Standard BP tempo uses Modified Base RT + two Basic Attack RT costs. Damage and RT Delay per 1000 CT include this Base RT cycle cost.
A8: Scope | B8: This workbook builds, audits, and stress-tests approved or explicitly provisional base-weapon endpoints using the current approximately 1,000 BP model. It does not determine Skill Card balance, rarity bonus packages, Armor, Accessories, Shields, Armor Off-Hands, authored Unique exceptions, or final Focus endpoints.
A9: Architecture boundary | B9: Unified Skill Cards may explicitly inherit eligible main-hand weapon properties, but Skill formulas and inheritance percentages are Manual-owned and are not priced by this base-weapon Builder.
A10: Negative limits | B10: Base RT Delay minimum -150; target RT cannot go below 0; maximum negative RT Delay BP refund -100. Negative Weapon Defense cannot exceed the same-level balanced Armor Defense floor.
A11: Range rule | B11: Maximum Range and projectile Minimum Range are separate. Minimum Range refunds are capped at 50% of Maximum Range BP.
A12: Passive delivery | B12: Built-in weapon-passive delivery is passive-specific. A passive declares: - Compatible Skill effect tags - Compatible Target Rules - Effect - Delivery frequency - Timing - Restrictions Delivery may be: - Once per action - Once per affected target - Once per successful hit Basic Attacks use the weapon passive’s declared delivery behavior. For Skill Cards, compatibility must first be established through the Skill’s effect tags and Target Rules. Multi-hit and multi-target Skills repeat a passive only when the passive’s declared delivery rule permits repetition. Reduced Pattern damage does not reduce passive magnitude unless the passive explicitly scales from damage dealt. Weapon RT Delay applies to a Skill Card only when the Skill explicitly declares Weapon RT Delay Inheritance.
A13: Skill Card interaction boundary | B13: Any unified Skill Card may explicitly inherit eligible properties from its equipped main-hand weapon. Possible declared sources include: - Weapon Damage - Effective Weapon WT - Weapon RT Delay - Weapon Defense - Weapon Maximum Range - Weapon Minimum Range - Weapon Pattern - Projectile Type - Weapon tags and properties - Compatible weapon passives Inheritance is never automatic. Each Skill Card declares the inherited property, percentage or conversion, affected result, compatibility requirements, and exceptions. Maximum Range and Minimum Range remain part of a complete inherited ranged profile. Minimum Range drawbacks may not be silently discarded. The Weapon Builder prices the base weapon profile. It does not price the Skill Card that inherits the profile.
A14: Pattern ownership | B14: Base-pattern BP valuation and procedural rarity Pattern-conversion prices are separate systems. This Builder values the complete base-weapon Pattern using the base Pattern BP model. Procedural Line 2, Impact Splash, Cleave, Cone, Adjacent, and Chain conversions are rarity bonus attributes priced separately by the Manual and remain outside this base-endpoint Builder. A procedural Pattern conversion applies to a Skill only when the Skill explicitly inherits Weapon Pattern.
A15: Use | B15: Edit Weapon Builder inputs, review BP and cycle outputs, then inspect Stress Tests and Validation.
... A21: Status | B21: Audit record

Sheet BP Controls
A1: BP Controls and Formula Ownership
A2: Working controls. Change only during deliberate recalibration.
A3: Control | B3: Value | C3: Meaning
A4: Target BP | B4: 1000 | C4: Expected normal base-weapon endpoint budget.
A5: 1H flexibility BP | B5: 350 | C5: Cost of keeping off-hand capacity; 2H cost is 0.
A6: Attack coefficient | B6: 350 | C6: Attack BP at Rating 100.
A7: Attack exponent | B7: 1.4 | C7: Curvature of attack pricing.
A8: High Attack threshold | B8: 125 | C8: Premium begins above this Attack Rating.
A9: High Attack cap | B9: 400 | C9: Maximum burst premium.
A10: High Attack decay | B10: 14 | C10: Speed at which premium approaches cap.
A11: WT coefficient | B11: 350 | C11: Tempo pricing scale against Sword.
A12: WT exponent | B12: 1.5 | C12: Tempo curvature.
A13: Defense coefficient | B13: 300 | C13: Realized durability pricing scale.
A14: Defense exponent | B14: 1.25 | C14: Durability curve.
A15: RT Delay coefficient | B15: 200 | C15: Timeline-control pricing at Rating 100.
... A28: Expected attacks per cycle | B28: 2 | C28: Standard Basic Attack tempo assumption.
A32: Maximum Range | B32: Range BP | C32: Defense Realization
A33: 1 | B33: =ROUND(RangeBase+RangeCoeff*(A33-1)^RangeExp,0) -> 100 | C33: 1
A34: 2 | B34: =ROUND(RangeBase+RangeCoeff*(A34-1)^RangeExp,0) -> 180 | C34: 0.8
A35: 3 | B35: =ROUND(RangeBase+RangeCoeff*(A35-1)^RangeExp,0) -> 311 | C35: 0.65
A36: 4 | B36: =ROUND(RangeBase+RangeCoeff*(A36-1)^RangeExp,0) -> 472 | C36: 0.5
A37: 5 | B37: =ROUND(RangeBase+RangeCoeff*(A37-1)^RangeExp,0) -> 657 | C37: 0.4
A38: 6 | B38: =ROUND(RangeBase+RangeCoeff*(A38-1)^RangeExp,0) -> 861 | C38: 0.35
A39: 7 | B39: =ROUND(RangeBase+RangeCoeff*(A39-1)^RangeExp,0) -> 1083 | C39: 0.35
A40: 8 | B40: =ROUND(RangeBase+RangeCoeff*(A40-1)^RangeExp,0) -> 1320 | C40: 0.35
A43: Pattern | B43: Secondary Equiv. | C43: Reliability | D43: Pattern BP
A44: Single | B44: 0 | C44: 1 | D44: =ROUND(PatternCoeff*B44^PatternExp*C44,0) -> 0
A45: Line 2 | B45: 1 | C45: 1 | D45: =ROUND(PatternCoeff*B45^PatternExp*C45,0) -> 400
A46: Cleave | B46: 1.5 | C46: 0.9 | D46: =ROUND(PatternCoeff*B46^PatternExp*C46,0) -> 598
A47: Impact Splash | B47: 1 | C47: 1 | D47: =ROUND(PatternCoeff*B47^PatternExp*C47,0) -> 400
A50: Passive | B50: BP | C50: Status / Builder Use
A51: None | B51: 0 | C51: Approved
A52: Bleeding Edge | B52: 200 | C52: Approved; Direct Damage + Enemy Unit; per successful hit
A53: Toxic Blade | B53: 150 | C53: Approved; Direct Damage + Enemy Unit; per successful hit
A54: Venomous | B54: 200 | C54: Approved; Direct Damage + Enemy Unit; per successful hit after damage
A55: Burning | B55: 200 | C55: Approved elemental conversion; eligible Physical Direct Damage + Enemy Unit
A56: Freezing | B56: 150 | C56: Approved elemental conversion; eligible Physical Direct Damage + Enemy Unit
A57: Blinding | B57: 150 | C57: Approved; Direct Damage + Enemy Unit; per successful hit
A58: Crippling | B58: 200 | C58: Approved; Direct Damage + Enemy Unit; per successful hit
A59: Mana Burn | B59: 200 | C59: Approved passive price; Mana Burn numerical simulation remains pending
...

Sheet Archetypes
A1: Current Provisional Weapon Archetypes
A2: The 15 conventional weapon archetypes are provisional working endpoints. The catalog is incomplete and has no fixed final archetype count. Dagger remains provisional pending its base-passive definition.
A3: Weapon | B3: Family | C3: Projectile | D3: Hands | E3: Min Range | F3: Max Range | G3: Pattern | H3: Passive | I3: L1 Damage | J3: L1 WT | K3: L1 Delay | L3: L1 Defense | M3: L99 Damage | N3: L99 WT | O3: L99 Delay | P3: L99 Defense | Q3: L1 BP | R3: L99 BP | S3: Role
A4: Sword | B4: Melee | C4: None | D4: 1H | E4: 1 | F4: 1 | G4: Single | H4: None | I4: 16 | J4: 30 | K4: 40 | L4: 2 | M4: 67 | N4: 60 | O4: 60 | P4: 5 | Q4: 1000 | R4: 1000 | S4: Balanced 1H reference
A5: Dagger | B5: Melee | C5: None | D5: 1H | E5: 1 | F5: 1 | G5: Single | H5: Piercing Edge / Brutal (Pending base-passive definition) | I5: 16 | J5: 10 | K5: 5 | L5: 4 | M5: 60 | N5: 10 | O5: 20 | P5: 6 | Q5: 1000 | R5: 996 | S5: Provisional Dagger endpoint. Piercing Edge / Brutal effect and BP allocation are pending. Do not use this row as a final passive-balanced simulation reference.
A6: Claws | B6: Melee | C6: None | D6: 2H | E6: 1 | F6: 1 | G6: Single | H6: None | I6: 14 | J6: 10 | K6: 80 | L6: -2 | M6: 51 | N6: 25 | O6: 120 | P6: -5 | Q6: 998 | R6: 999 | S6: Sustained RT control
A7: Hammer | B7: Melee | C7: None | D7: 2H | E7: 1 | F7: 1 | G7: Single | H7: None | I7: 21 | J7: 80 | K7: 65 | L7: 2 | M7: 86 | N7: 135 | O7: 115 | P7: 5 | Q7: 1000 | R7: 1001 | S7: Heavy impact and delay
A8: Greatsword | B8: Melee | C8: None | D8: 2H | E8: 1 | F8: 1 | G8: Cleave | H8: None | I8: 16 | J8: 75 | K8: 20 | L8: -1 | M8: 70 | N8: 165 | O8: 25 | P8: 0 | Q8: 1000 | R8: 998 | S8: Melee Cleave
A9: Spear | B9: Melee | C9: None | D9: 2H | E9: 1 | F9: 2 | G9: Line 2 | H9: None | I9: 13 | J9: 45 | K9: 30 | L9: 7 | M9: 56 | N9: 90 | O9: 50 | P9: 23 | Q9: 1001 | R9: 1005 | S9: Range-2 line
A10: Whip | B10: Melee | C10: None | D10: 1H | E10: 1 | F10: 3 | G10: Single | H10: None | I10: 13 | J10: 45 | K10: 30 | L10: 0 | M10: 52 | N10: 80 | O10: 45 | P10: 0 | Q10: 1004 | R10: 998 | S10: Safe melee reach
A11: Club | B11: Melee | C11: None | D11: 1H | E11: 1 | F11: 1 | G11: Single | H11: Push / Knockback 1 | I11: 12 | J11: 50 | K11: 25 | L11: 7 | M11: 53 | N11: 90 | O11: 45 | P11: 16 | Q11: 1000 | R11: 1004 | S11: Durable displacement
A12: War Axe | B12: Melee | C12: None | D12: 2H | E12: 1 | F12: 1 | G12: Single | H12: None | I12: 25 | J12: 95 | K12: 25 | L12: -5 | M12: 105 | N12: 165 | O12: 35 | P12: -21 | Q12: 1002 | R12: 1004 | S12: Extreme burst
A13: Longbow | B13: Ranged | C13: Arc | D13: 2H | E13: 2 | F13: 5 | G13: Single | H13: None | I13: 18 | J13: 80 | K13: 25 | L13: -2 | M13: 75 | N13: 145 | O13: 40 | P13: -5 | Q13: 998 | R13: 999 | S13: Long-range damage
A14: Hand Crossbow | B14: Ranged | C14: Direct | D14: 1H | E14: 2 | F14: 4 | G14: Single | H14: None | I14: 12 | J14: 75 | K14: 25 | L14: 0 | M14: 47 | N14: 120 | O14: 40 | P14: 0 | Q14: 1000 | R14: 998 | S14: Flexible 1H ranged
A15: Sling | B15: Ranged | C15: Arc | D15: 1H | E15: 2 | F15: 3 | G15: Single | H15: None | I15: 11 | J15: 20 | K15: 35 | L15: 2 | M15: 46 | N15: 35 | O15: 50 | P15: 0 | Q15: 1001 | R15: 1000 | S15: Fast arcing harassment
... A18: Repeating Crossbow | B18: Ranged | C18: Direct | D18: 2H | E18: 2 | F18: 4 | G18: Single | H18: None | I18: 9 | J18: 45 | K18: 80 | L18: -3 | M18: 36 | N18: 75 | O18: 115 | P18: -5 | Q18: 1000 | R18: 999 | S18: Ranged RT control
A20: Focus Weapon Family
A21: Status | B21: Approved conceptual weapon family; exact passive definitions, prices, and archetype endpoints pending
A22: Builder ownership | B22: Focus uses the same approximately 1,000 BP base target, normal weapon BP curves, handedness pricing, Damage, WT, RT Delay, Defense, Range, Pattern, passive, and applicable synergy pricing as other weapon families.
A23: Skill interaction | B23: Focus is a normal weapon whose built-in passive is designed to improve eligible Skill Cards. Focus may Basic Attack and may provide explicitly inherited properties to compatible Skills. Focus is not the only weapon family whose properties Skills may inherit.
A24: WT | B24: STR reduces Focus WT through the normal weapon-WT rule. INT does not reduce Focus WT.
A25: Power | B25: Focus does not provide Spell Power and does not replace a Skill Card’s authored Power Formula.
A26: Passive pricing | B26: Focus passives use normal passive pricing. There is no automatic surcharge, discount, mandatory passive reserve, or separate Focus BP curve merely because the weapon is a Focus.
A27: Range identity / Off-hand | B27: Built-in Bonus Skill Range remains mainly a 2H Focus identity. Eligible 1H Focus may receive Bonus Skill Range through procedural rarity when budget, line count, family eligibility, and validation permit. Off-hand Focus is conceptually permitted, but its BP framework remains parked.

Sheet Weapon Builder
A1: Interactive Weapon BP Builder
A2: Blue cells are editable. White cells calculate. Complete-cycle outputs include Base RT plus two Basic Attacks. Projectile Type controls Minimum Range refund eligibility.
A3: Weapon Inputs | D3: Calculated BP | G3: Combat / Cycle Outputs
A4: Name | B4: Sword | D4: Attack BP | E4: =ROUND(AttackCoeff*(H4/100)^AttackExp,0)+IF(H4>HighThreshold,ROUND(HighCap*(1-EXP(-(H4-HighThreshold)/HighDecay)),0),0) -> 350 | G4: Attack Rating | H4: =100*B5/B22 -> 100
A5: Weapon Damage | B5: 67 | D5: WT BP | E5: =ROUND(WTCoeff*((H11/H12)^WTExp-1),0) -> 0 | G5: Effective Weapon WT | H5: =B6*(1-B17/(200+B17)) -> 45.540797
A6: Weapon WT | B6: 60 | D6: Defense BP | E6: =ROUND(ROUND(DefCoeff*((H21/H18)^DefExp-1),0)*VLOOKUP(B11,RangeTable,3,FALSE),0) -> 0 | G6: Basic Attack RT | H6: =ROUND(H8*0.1,0)+H5 -> 91.540797
A7: RT Delay | B7: 60 | D7: RT Delay BP | E7: =IF(B7>=0,ROUND(DelayCoeff*(MAX(0,H13)/100)^DelayExp,0),MAX(NegDelayRefund,-ROUND(DelayCoeff*(ABS(H13)/100)^DelayExp,0))) -> 200 | G7: Sword Basic Attack RT | H7: =ROUND(H8*0.1,0)+B23*(1-B17/(200+B17)) -> 91.540797
A8: Weapon Defense | B8: 5 | D8: Hand BP | E8: =IF(B9="1H",OneHBP,0) -> 350 | G8: Modified Base RT | H8: =B19+B20*(1-B17/(200+B17)) -> 460.72106
A9: Hand Type | B9: 1H | D9: Maximum Range BP | E9: =ROUND(RangeBase+RangeCoeff*(B11-1)^RangeExp,0) -> 100 | G9: Two-Attack Cycle RT | H9: =H8+ExpectedAttacks*H6 -> 643.80266
A10: Minimum Range | B10: 1 | D10: Minimum Range Refund | E10: =IF(OR(B29="None",B10<=1),0,-MIN(E9*MinRefundCap,ROUND(MinRefundCoeff*(B10-1)^RangeExp,0))) -> 0 | G10: Sword Two-Attack Cycle RT | H10: =H8+ExpectedAttacks*H7 -> 643.80266
A11: Maximum Range | B11: 1 | D11: Pattern BP | E11: =VLOOKUP(B12,PatternBPTable,4,FALSE) -> 0 | G11: Attacks per 1000 CT | H11: =ExpectedAttacks*1000/H9 -> 3.106542
A12: Pattern | B12: Single | D12: Passive BP | E12: =IFERROR(VLOOKUP(B13,PassiveBPTable,2,FALSE),"N/A") -> 0 | G12: Sword Attacks per 1000 CT | H12: =ExpectedAttacks*1000/H10 -> 3.106542
A13: Passive | B13: None | D13: Tempo Synergy | E13: =MIN(TempoCap,ROUND(TempoFactor*SQRT(MAX(0,E5)*MAX(0,E7-DelayCoeff)),0)) -> 0 | G13: RT Delay Rating | H13: =IF(B7=0,0,100*(ExpectedAttacks*B7/H9)/(ExpectedAttacks*B24/H10)) -> 100
D14: Total BP | E14: =SUM(E4:E13) -> 1000 | G14: Final Damage / Attack | H14: =IF((B27*(1+B18/300))>=0,((B5*(1+B17/200))^2)/((B5*(1+B17/200))+(B27*(1+B18/300))),B5*(1+B17/200)+ABS(B27*(1+B18/300))) -> 54.567022
A15: Scenario Benchmark | D15: Variance | E15: =E14-TargetBP -> 0 | G15: HP Removed / Attack | H15: =H14/B26 -> 0.17949678
A16: Endpoint | B16: Level 99 | D16: Budget Status | E16: =IF(B13="None",IF(ABS(E15)<=50,"Near target",IF(E15>50,"Over budget","Under budget")),IFERROR(IF(LEFT(VLOOKUP(B13,PassiveBPTable,3,FALSE),8)="Approved",IF(ABS(E15)<=50,"Near target",IF(E15>50,"Over budget","Under budget")),IF(B13="Push / Knockback 1","REVIEW: provisional Club endpoint allocation","INVALID: parked or undefined passive")),"INVALID: parked or undefined passive")) -> Near target | G16: Damage per 1000 CT | H16: =ExpectedAttacks*H14/H9*1000 -> 169.51474
A17: STR | B17: 63.5 | G17: Raw RT Delay per 1000 CT | H17: =ExpectedAttacks*B7/H9*1000 -> 186.39252
A18: VIT | B18: 63.5 | G18: Incoming Damage | H18: =IF((H20*(1+B18/300))>=0,((B22*(1+B17/200))^2)/((B22*(1+B17/200))+(H20*(1+B18/300))),B22*(1+B17/200)+ABS(H20*(1+B18/300))) -> 54.567022
A19: Base RT | B19: 400 | D19: Validation Notes
A20: Armor WT | B20: 80 | D20: B7 | E20: =IF(B7<NegDelayFloor,"ERROR: RT Delay below -150 floor","RT Delay floor valid") -> RT Delay floor valid | G20: Effective Total Defense | H20: =B21+B8 -> 45
A21: Armor Defense | B21: 40 | D21: B10 | E21: =IF(B10>B11,"ERROR: Minimum Range exceeds Maximum Range","Range bounds valid") -> Range bounds valid | G21: Reference Incoming Damage | H21: =IF(((B21+B25)*(1+B18/300))>=0,((B22*(1+B17/200))^2)/((B22*(1+B17/200))+((B21+B25)*(1+B18/300))),B22*(1+B17/200)+ABS((B21+B25)*(1+B18/300))) -> 54.567022
A22: Sword Damage | B22: 67 | D22: B8 | E22: =IF(B8<-B21,"ERROR: Weapon Defense below balanced Armor Defense floor","Defense floor valid") -> Defense floor valid
A23: Sword WT | B23: 60 | D23: B13 | E23: =IF(B13="None","No built-in passive.",IFERROR(IF(LEFT(VLOOKUP(B13,PassiveBPTable,3,FALSE),8)="Approved","Passive price approved for current Builder use.",IF(B13="Push / Knockback 1","REVIEW: provisional base-archetype passive allocation.","INVALID: "&B13&" effect and/or final BP price is not approved.")),"INVALID: "&B13&" effect and/or final BP price is not approved.")) -> No built-in passive.
A24: Sword RT Delay | B24: 60
A25: Sword Defense | B25: 5
A26: Target Max HP | B26: 304
A27: Target Defense | B27: 45
A29: Projectile Type | B29: None

Sheet Stress Tests
A1: Stress Tests
A2: Scenario sweeps use the current Weapon Builder inputs and complete-cycle throughput.
A3: Target Defense | B3: Damage / Attack | C3: HP Removed | D3: Damage / 1000 CT | E3: Delay / 1000 CT | F3: Cycle RT | G3: Attacks / 1000 | H3: Notes
A4: -40 | B4: =IF((A4*(1+'Weapon Builder'!$B$18/300))>=0,(('Weapon Builder'!$B$5*(1+'Weapon Builder'!$B$17/200))^2)/(('Weapon Builder'!$B$5*(1+'Weapon Builder'!$B$17/200))+(A4*(1+'Weapon Builder'!$B$18/300))),'Weapon Builder'!$B$5*(1+'Weapon Builder'!$B$17/200)+ABS(A4*(1+'Weapon Builder'!$B$18/300))) -> 136.73917 | C4: =B4/'Weapon Builder'!$B$26 -> 0.44979989 | D4: =ExpectedAttacks*B4/'Weapon Builder'!$H$9*1000 -> 424.78597 | E4: ='Weapon Builder'!$H$17 -> 186.39252 | F4: ='Weapon Builder'!$H$9 -> 643.80266 | G4: ='Weapon Builder'!$H$11 -> 3.106542 | H4: Editable Defense case
A5: -20 | B5: =IF((A5*(1+'Weapon Builder'!$B$18/300))>=0,(('Weapon Builder'!$B$5*(1+'Weapon Builder'!$B$17/200))^2)/(('Weapon Builder'!$B$5*(1+'Weapon Builder'!$B$17/200))+(A5*(1+'Weapon Builder'!$B$18/300))),'Weapon Builder'!$B$5*(1+'Weapon Builder'!$B$17/200)+ABS(A5*(1+'Weapon Builder'!$B$18/300))) -> 112.50583 | C5: =B5/'Weapon Builder'!$B$26 -> 0.37008498 | D5: =ExpectedAttacks*B5/'Weapon Builder'!$H$9*1000 -> 349.5041 | E5: ='Weapon Builder'!$H$17 -> 186.39252 | F5: ='Weapon Builder'!$H$9 -> 643.80266 | G5: ='Weapon Builder'!$H$11 -> 3.106542 | H5: Editable Defense case
A6: 0 | B6: =IF((A6*(1+'Weapon Builder'!$B$18/300))>=0,(('Weapon Builder'!$B$5*(1+'Weapon Builder'!$B$17/200))^2)/(('Weapon Builder'!$B$5*(1+'Weapon Builder'!$B$17/200))+(A6*(1+'Weapon Builder'!$B$18/300))),'Weapon Builder'!$B$5*(1+'Weapon Builder'!$B$17/200)+ABS(A6*(1+'Weapon Builder'!$B$18/300))) -> 88.2725 | C6: =B6/'Weapon Builder'!$B$26 -> 0.29037007 | D6: =ExpectedAttacks*B6/'Weapon Builder'!$H$9*1000 -> 274.22223 | E6: ='Weapon Builder'!$H$17 -> 186.39252 | F6: ='Weapon Builder'!$H$9 -> 643.80266 | G6: ='Weapon Builder'!$H$11 -> 3.106542 | H6: Editable Defense case
A7: 20 | B7: =IF((A7*(1+'Weapon Builder'!$B$18/300))>=0,(('Weapon Builder'!$B$5*(1+'Weapon Builder'!$B$17/200))^2)/(('Weapon Builder'!$B$5*(1+'Weapon Builder'!$B$17/200))+(A7*(1+'Weapon Builder'!$B$18/300))),'Weapon Builder'!$B$5*(1+'Weapon Builder'!$B$17/200)+ABS(A7*(1+'Weapon Builder'!$B$18/300))) -> 69.258936 | C7: =B7/'Weapon Builder'!$B$26 -> 0.22782545 | D7: =ExpectedAttacks*B7/'Weapon Builder'!$H$9*1000 -> 215.15579 | E7: ='Weapon Builder'!$H$17 -> 186.39252 | F7: ='Weapon Builder'!$H$9 -> 643.80266 | G7: ='Weapon Builder'!$H$11 -> 3.106542 | H7: Editable Defense case
A8: 45 | B8: =IF((A8*(1+'Weapon Builder'!$B$18/300))>=0,(('Weapon Builder'!$B$5*(1+'Weapon Builder'!$B$17/200))^2)/(('Weapon Builder'!$B$5*(1+'Weapon Builder'!$B$17/200))+(A8*(1+'Weapon Builder'!$B$18/300))),'Weapon Builder'!$B$5*(1+'Weapon Builder'!$B$17/200)+ABS(A8*(1+'Weapon Builder'!$B$18/300))) -> 54.567022 | C8: =B8/'Weapon Builder'!$B$26 -> 0.17949678 | D8: =ExpectedAttacks*B8/'Weapon Builder'!$H$9*1000 -> 169.51474 | E8: ='Weapon Builder'!$H$17 -> 186.39252 | F8: ='Weapon Builder'!$H$9 -> 643.80266 | G8: ='Weapon Builder'!$H$11 -> 3.106542 | H8: Editable Defense case
A9: 60 | B9: =IF((A9*(1+'Weapon Builder'!$B$18/300))>=0,(('Weapon Builder'!$B$5*(1+'Weapon Builder'!$B$17/200))^2)/(('Weapon Builder'!$B$5*(1+'Weapon Builder'!$B$17/200))+(A9*(1+'Weapon Builder'!$B$18/300))),'Weapon Builder'!$B$5*(1+'Weapon Builder'!$B$17/200)+ABS(A9*(1+'Weapon Builder'!$B$18/300))) -> 48.405996 | C9: =B9/'Weapon Builder'!$B$26 -> 0.15923025 | D9: =ExpectedAttacks*B9/'Weapon Builder'!$H$9*1000 -> 150.37526 | E9: ='Weapon Builder'!$H$17 -> 186.39252 | F9: ='Weapon Builder'!$H$9 -> 643.80266 | G9: ='Weapon Builder'!$H$11 -> 3.106542 | H9: Editable Defense case
A10: 90 | B10: =IF((A10*(1+'Weapon Builder'!$B$18/300))>=0,(('Weapon Builder'!$B$5*(1+'Weapon Builder'!$B$17/200))^2)/(('Weapon Builder'!$B$5*(1+'Weapon Builder'!$B$17/200))+(A10*(1+'Weapon Builder'!$B$18/300))),'Weapon Builder'!$B$5*(1+'Weapon Builder'!$B$17/200)+ABS(A10*(1+'Weapon Builder'!$B$18/300))) -> 39.488828 | C10: =B10/'Weapon Builder'!$B$26 -> 0.12989746 | D10: =ExpectedAttacks*B10/'Weapon Builder'!$H$9*1000 -> 122.6737 | E10: ='Weapon Builder'!$H$17 -> 186.39252 | F10: ='Weapon Builder'!$H$9 -> 643.80266 | G10: ='Weapon Builder'!$H$11 -> 3.106542 | H10: Editable Defense case
A11: 120 | B11: =IF((A11*(1+'Weapon Builder'!$B$18/300))>=0,(('Weapon Builder'!$B$5*(1+'Weapon Builder'!$B$17/200))^2)/(('Weapon Builder'!$B$5*(1+'Weapon Builder'!$B$17/200))+(A11*(1+'Weapon Builder'!$B$18/300))),'Weapon Builder'!$B$5*(1+'Weapon Builder'!$B$17/200)+ABS(A11*(1+'Weapon Builder'!$B$18/300))) -> 33.345962 | C11: =B11/'Weapon Builder'!$B$26 -> 0.10969066 | D11: =ExpectedAttacks*B11/'Weapon Builder'!$H$9*1000 -> 103.59063 | E11: ='Weapon Builder'!$H$17 -> 186.39252 | F11: ='Weapon Builder'!$H$9 -> 643.80266 | G11: ='Weapon Builder'!$H$11 -> 3.106542 | H11: Editable Defense case
A15: Repeated Complete Cycles
A16: Cycles | B16: Attacks | C16: Total Damage | D16: Total CT | E16: Total Delay | F16: HP Removed | G16: Damage / 1000 | H16: Interpretation
A17: 1 | B17: =A17*ExpectedAttacks -> 2 | C17: =B17*'Weapon Builder'!$H$14 -> 109.13404 | D17: =A17*'Weapon Builder'!$H$9 -> 643.80266 | E17: =B17*'Weapon Builder'!$B$7 -> 120 | F17: =C17/'Weapon Builder'!$B$26 -> 0.35899356 | G17: =C17/D17*1000 -> 169.51474 | H17: =IF(F17>=1,"Defeats benchmark target","Target survives sequence") -> Target survives sequence
A18: 2 | B18: =A18*ExpectedAttacks -> 4 | C18: =B18*'Weapon Builder'!$H$14 -> 218.26809 | D18: =A18*'Weapon Builder'!$H$9 -> 1287.6053 | E18: =B18*'Weapon Builder'!$B$7 -> 240 | F18: =C18/'Weapon Builder'!$B$26 -> 0.71798713 | G18: =C18/D18*1000 -> 169.51474 | H18: =IF(F18>=1,"Defeats benchmark target","Target survives sequence") -> Target survives sequence
A19: 3 | B19: =A19*ExpectedAttacks -> 6 | C19: =B19*'Weapon Builder'!$H$14 -> 327.40213 | D19: =A19*'Weapon Builder'!$H$9 -> 1931.408 | E19: =B19*'Weapon Builder'!$B$7 -> 360 | F19: =C19/'Weapon Builder'!$B$26 -> 1.0769807 | G19: =C19/D19*1000 -> 169.51474 | H19: =IF(F19>=1,"Defeats benchmark target","Target survives sequence") -> Defeats benchmark target
A20: 4 | B20: =A20*ExpectedAttacks -> 8 | C20: =B20*'Weapon Builder'!$H$14 -> 436.53617 | D20: =A20*'Weapon Builder'!$H$9 -> 2575.2106 | E20: =B20*'Weapon Builder'!$B$7 -> 480 | F20: =C20/'Weapon Builder'!$B$26 -> 1.4359743 | G20: =C20/D20*1000 -> 169.51474 | H20: =IF(F20>=1,"Defeats benchmark target","Target survives sequence") -> Defeats benchmark target
A21: 5 | B21: =A21*ExpectedAttacks -> 10 | C21: =B21*'Weapon Builder'!$H$14 -> 545.67022 | D21: =A21*'Weapon Builder'!$H$9 -> 3219.0133 | E21: =B21*'Weapon Builder'!$B$7 -> 600 | F21: =C21/'Weapon Builder'!$B$26 -> 1.7949678 | G21: =C21/D21*1000 -> 169.51474 | H21: =IF(F21>=1,"Defeats benchmark target","Target survives sequence") -> Defeats benchmark target
A24: Synergy / Limit Flags
A25: Tempo Control | B25: =IF(AND('Weapon Builder'!$E$5>0,'Weapon Builder'!$E$7>DelayCoeff),"TRIGGERED","No") -> No | C25: Positive WT BP plus excess RT Delay
A26: Safe Artillery | B26: =IF(AND('Weapon Builder'!$H$4>110,'Weapon Builder'!$B$11>=4),"REVIEW","No") -> No | C26: High Attack plus Range 4+
A27: Alpha Strike | B27: =IF(AND('Weapon Builder'!$H$4>125,'Weapon Builder'!$H$6<'Weapon Builder'!$H$7),"REVIEW","No") -> No | C27: High Attack plus faster-than-Sword tempo
A28: Repeated Delivery | B28: =IF(OR('Weapon Builder'!$B$12<>"Single",IFERROR(ISNUMBER(SEARCH("per successful hit",VLOOKUP('Weapon Builder'!$B$13,PassiveBPTable,3,FALSE))),FALSE),IFERROR(ISNUMBER(SEARCH("per qualifying damage hit",VLOOKUP('Weapon Builder'!$B$13,PassiveBPTable,3,FALSE))),FALSE)),"REVIEW","No") -> No | C28: REVIEW when the selected Pattern, passive, or authored action can create repeated delivery. Delivery frequency is passive-specific and must not be assumed from hit count alone.
A29: Negative Delay Floor | B29: =IF('Weapon Builder'!$B$7<NegDelayFloor,"ERROR","Valid") -> Valid | C29: Minimum base RT Delay -150
A30: Defense Floor | B30: =IF('Weapon Builder'!$B$8<-'Weapon Builder'!$B$21,"ERROR","Valid") -> Valid | C30: Cannot exceed balanced Armor Defense floor
A31: Projectile Minimum Range | B31: =IF(AND('Weapon Builder'!$B$29="None",'Weapon Builder'!$B$10>1),"ERROR","Valid") -> Valid | C31: Minimum Range refund requires Direct or Arc projectile type

Sheet Validation
A1: Builder Validation and Current Boundaries
A2: Cross-check against the current audited Manual and Architecture.
A3: Check | B3: Status | C3: Details
A4: Timing basis | B4: PASS | C4: Basic Attack RT uses 10% Modified Base RT plus Effective Weapon WT.
A5: Complete-cycle throughput | B5: PASS | C5: Includes Modified Base RT plus two Basic Attacks.
A6: Current archetypes | B6: PASS WITH PROVISIONAL NOTE | C6: 15 conventional working endpoints preserved; catalog incomplete; Dagger passive pending.
A7: Minimum range | B7: PASS | C7: Projectile Minimum Range refund is separate and capped.
A8: Negative RT Delay | B8: PASS | C8: Base floor -150; target RT floor belongs to combat resolution; refund capped at -100 BP.
A9: Negative Defense | B9: PASS | C9: Weapon Defense floor uses same-level balanced Armor Defense.
A10: Passive catalog | B10: PASS WITH PARKED ITEMS | C10: Approved prices corrected. Undefined and parked passives are excluded from normal valid Builder use.
A11: Passive delivery | B11: PASS | C11: Passive-specific delivery is required. Delivery may be once per action, affected target, or successful hit. Skill compatibility uses declared effect tags and Target Rules. Weapon RT Delay applies to Skills only through explicit inheritance.
A12: Unified Skill inheritance | B12: PASS | C12: Base weapon properties may be explicitly inherited by eligible Skill Cards; inheritance is Skill-authored and outside BP calculation.
A13: Pattern boundary | B13: PASS | C13: Base Pattern valuation is separate from procedural Pattern-conversion pricing.
A14: Focus boundary | B14: PASS | C14: Focus uses normal weapon BP rules; numerical endpoints and passive prices remain pending.
... A18: Source hierarchy | B18: PASS | C18: Newest approved decision, then Manual, Architecture, Builder.
A19: Formula integrity | B19: {=IF(SUMPRODUCT(--ISERROR('Weapon Builder'!A1:H29))+SUMPRODUCT(--ISERROR('Stress Tests'!A1:H31))+SUMPRODUCT(--ISERROR('BP Controls'!A1:D78))+SUMPRODUCT(--ISERROR(Archetypes!A1:S27))=0,"PASS","FAIL")} -> PASS | C19: =IF(B19="PASS","No spreadsheet formula errors detected.","Spreadsheet formula errors require review.") -> No spreadsheet formula errors detected.
A20: Target mapping | B20: PASS | C20: HP Removed uses Target Max HP; damage uses Target Defense.
A21: Defense references | B21: PASS | C21: Incoming and reference damage use Armor Defense plus weapon or Sword Defense.
A22: Default reference | B22: =IF(AND('Weapon Builder'!B4="Sword",'Weapon Builder'!B13="None",ABS('Weapon Builder'!E14-TargetBP)<=1),"PASS","REVIEW") -> PASS | C22: =IF(B22="PASS","Level 99 Sword reproduces the working approximately 1,000 BP endpoint.","Default Sword inputs or BP result require review.") -> Level 99 Sword reproduces the working approximately 1,000 BP endpoint.
A23: Projectile eligibility | B23: PASS | C23: Minimum Range refund requires Direct or Arc projectile type.
